<?xml version="1.0" encoding="UTF-8"?>
<testsuite name="查询运费"
           tests="9"
           failures="6"
           errors="0"
           skipped="0"
           time="1.205">
  <properties />
            <testcase name="feeTest5" time="0.097" classname="com.edu.test.TransFeeTest">
                <failure type="java.lang.AssertionError"
                  message="expected [请求失败] but found [success]"
              >
<![CDATA[java.lang.AssertionError: expected [请求失败] but found [success]
  org.testng.Assert.fail(Assert.java:96)
  org.testng.Assert.failNotEquals(Assert.java:776)
  org.testng.Assert.assertEqualsImpl(Assert.java:137)
  org.testng.Assert.assertEquals(Assert.java:118)
  org.testng.Assert.assertEquals(Assert.java:453)
  org.testng.Assert.assertEquals(Assert.java:463)
  com.edu.test.TransFeeTest.feeTest5(TransFeeTest.java:66)
  java.base/jdk.internal.reflect.NativeMethodAccessorImpl.invoke0(Native Method)
  java.base/jdk.internal.reflect.NativeMethodAccessorImpl.invoke(NativeMethodAccessorImpl.java:62)
  java.base/jdk.internal.reflect.DelegatingMethodAccessorImpl.invoke(DelegatingMethodAccessorImpl.java:43)
  java.base/java.lang.reflect.Method.invoke(Method.java:564)
  org.testng.internal.MethodInvocationHelper.invokeMethod(MethodInvocationHelper.java:124)
  org.testng.internal.Invoker.invokeMethod(Invoker.java:580)
  org.testng.internal.Invoker.invokeTestMethod(Invoker.java:716)
  org.testng.internal.Invoker.invokeTestMethods(Invoker.java:988)
  org.testng.internal.TestMethodWorker.invokeTestMethods(TestMethodWorker.java:125)
  org.testng.internal.TestMethodWorker.run(TestMethodWorker.java:109)
  org.testng.TestRunner.privateRun(TestRunner.java:648)
  org.testng.TestRunner.run(TestRunner.java:505)
  org.testng.SuiteRunner.runTest(SuiteRunner.java:455)
  org.testng.SuiteRunner.access$000(SuiteRunner.java:40)
  org.testng.SuiteRunner$SuiteWorker.run(SuiteRunner.java:489)
  org.testng.internal.thread.ThreadUtil$1.call(ThreadUtil.java:52)
  java.base/java.util.concurrent.FutureTask.run(FutureTask.java:264)
  java.base/java.util.concurrent.ThreadPoolExecutor.runWorker(ThreadPoolExecutor.java:1167)
  java.base/java.util.concurrent.ThreadPoolExecutor$Worker.run(ThreadPoolExecutor.java:641)
  java.base/java.lang.Thread.run(Thread.java:844)
]]>
      </failure>

          </testcase>
            <testcase name="feeTest9" time="0.082" classname="com.edu.test.TransFeeTest">
                <failure type="java.lang.AssertionError"
                  message="expected [请求失败] but found [success]"
              >
<![CDATA[java.lang.AssertionError: expected [请求失败] but found [success]
  org.testng.Assert.fail(Assert.java:96)
  org.testng.Assert.failNotEquals(Assert.java:776)
  org.testng.Assert.assertEqualsImpl(Assert.java:137)
  org.testng.Assert.assertEquals(Assert.java:118)
  org.testng.Assert.assertEquals(Assert.java:453)
  org.testng.Assert.assertEquals(Assert.java:463)
  com.edu.test.TransFeeTest.feeTest9(TransFeeTest.java:105)
  java.base/jdk.internal.reflect.NativeMethodAccessorImpl.invoke0(Native Method)
  java.base/jdk.internal.reflect.NativeMethodAccessorImpl.invoke(NativeMethodAccessorImpl.java:62)
  java.base/jdk.internal.reflect.DelegatingMethodAccessorImpl.invoke(DelegatingMethodAccessorImpl.java:43)
  java.base/java.lang.reflect.Method.invoke(Method.java:564)
  org.testng.internal.MethodInvocationHelper.invokeMethod(MethodInvocationHelper.java:124)
  org.testng.internal.Invoker.invokeMethod(Invoker.java:580)
  org.testng.internal.Invoker.invokeTestMethod(Invoker.java:716)
  org.testng.internal.Invoker.invokeTestMethods(Invoker.java:988)
  org.testng.internal.TestMethodWorker.invokeTestMethods(TestMethodWorker.java:125)
  org.testng.internal.TestMethodWorker.run(TestMethodWorker.java:109)
  org.testng.TestRunner.privateRun(TestRunner.java:648)
  org.testng.TestRunner.run(TestRunner.java:505)
  org.testng.SuiteRunner.runTest(SuiteRunner.java:455)
  org.testng.SuiteRunner.access$000(SuiteRunner.java:40)
  org.testng.SuiteRunner$SuiteWorker.run(SuiteRunner.java:489)
  org.testng.internal.thread.ThreadUtil$1.call(ThreadUtil.java:52)
  java.base/java.util.concurrent.FutureTask.run(FutureTask.java:264)
  java.base/java.util.concurrent.ThreadPoolExecutor.runWorker(ThreadPoolExecutor.java:1167)
  java.base/java.util.concurrent.ThreadPoolExecutor$Worker.run(ThreadPoolExecutor.java:641)
  java.base/java.lang.Thread.run(Thread.java:844)
]]>
      </failure>

          </testcase>
            <testcase name="feeTest6" time="0.095" classname="com.edu.test.TransFeeTest">
                <failure type="java.lang.AssertionError"
                  message="expected [请求失败] but found [success]"
              >
<![CDATA[java.lang.AssertionError: expected [请求失败] but found [success]
  org.testng.Assert.fail(Assert.java:96)
  org.testng.Assert.failNotEquals(Assert.java:776)
  org.testng.Assert.assertEqualsImpl(Assert.java:137)
  org.testng.Assert.assertEquals(Assert.java:118)
  org.testng.Assert.assertEquals(Assert.java:453)
  org.testng.Assert.assertEquals(Assert.java:463)
  com.edu.test.TransFeeTest.feeTest6(TransFeeTest.java:74)
  java.base/jdk.internal.reflect.NativeMethodAccessorImpl.invoke0(Native Method)
  java.base/jdk.internal.reflect.NativeMethodAccessorImpl.invoke(NativeMethodAccessorImpl.java:62)
  java.base/jdk.internal.reflect.DelegatingMethodAccessorImpl.invoke(DelegatingMethodAccessorImpl.java:43)
  java.base/java.lang.reflect.Method.invoke(Method.java:564)
  org.testng.internal.MethodInvocationHelper.invokeMethod(MethodInvocationHelper.java:124)
  org.testng.internal.Invoker.invokeMethod(Invoker.java:580)
  org.testng.internal.Invoker.invokeTestMethod(Invoker.java:716)
  org.testng.internal.Invoker.invokeTestMethods(Invoker.java:988)
  org.testng.internal.TestMethodWorker.invokeTestMethods(TestMethodWorker.java:125)
  org.testng.internal.TestMethodWorker.run(TestMethodWorker.java:109)
  org.testng.TestRunner.privateRun(TestRunner.java:648)
  org.testng.TestRunner.run(TestRunner.java:505)
  org.testng.SuiteRunner.runTest(SuiteRunner.java:455)
  org.testng.SuiteRunner.access$000(SuiteRunner.java:40)
  org.testng.SuiteRunner$SuiteWorker.run(SuiteRunner.java:489)
  org.testng.internal.thread.ThreadUtil$1.call(ThreadUtil.java:52)
  java.base/java.util.concurrent.FutureTask.run(FutureTask.java:264)
  java.base/java.util.concurrent.ThreadPoolExecutor.runWorker(ThreadPoolExecutor.java:1167)
  java.base/java.util.concurrent.ThreadPoolExecutor$Worker.run(ThreadPoolExecutor.java:641)
  java.base/java.lang.Thread.run(Thread.java:844)
]]>
      </failure>

          </testcase>
            <testcase name="feeTest7" time="0.098" classname="com.edu.test.TransFeeTest">
                <failure type="java.lang.AssertionError"
                  message="expected [请求失败] but found [success]"
              >
<![CDATA[java.lang.AssertionError: expected [请求失败] but found [success]
  org.testng.Assert.fail(Assert.java:96)
  org.testng.Assert.failNotEquals(Assert.java:776)
  org.testng.Assert.assertEqualsImpl(Assert.java:137)
  org.testng.Assert.assertEquals(Assert.java:118)
  org.testng.Assert.assertEquals(Assert.java:453)
  org.testng.Assert.assertEquals(Assert.java:463)
  com.edu.test.TransFeeTest.feeTest7(TransFeeTest.java:82)
  java.base/jdk.internal.reflect.NativeMethodAccessorImpl.invoke0(Native Method)
  java.base/jdk.internal.reflect.NativeMethodAccessorImpl.invoke(NativeMethodAccessorImpl.java:62)
  java.base/jdk.internal.reflect.DelegatingMethodAccessorImpl.invoke(DelegatingMethodAccessorImpl.java:43)
  java.base/java.lang.reflect.Method.invoke(Method.java:564)
  org.testng.internal.MethodInvocationHelper.invokeMethod(MethodInvocationHelper.java:124)
  org.testng.internal.Invoker.invokeMethod(Invoker.java:580)
  org.testng.internal.Invoker.invokeTestMethod(Invoker.java:716)
  org.testng.internal.Invoker.invokeTestMethods(Invoker.java:988)
  org.testng.internal.TestMethodWorker.invokeTestMethods(TestMethodWorker.java:125)
  org.testng.internal.TestMethodWorker.run(TestMethodWorker.java:109)
  org.testng.TestRunner.privateRun(TestRunner.java:648)
  org.testng.TestRunner.run(TestRunner.java:505)
  org.testng.SuiteRunner.runTest(SuiteRunner.java:455)
  org.testng.SuiteRunner.access$000(SuiteRunner.java:40)
  org.testng.SuiteRunner$SuiteWorker.run(SuiteRunner.java:489)
  org.testng.internal.thread.ThreadUtil$1.call(ThreadUtil.java:52)
  java.base/java.util.concurrent.FutureTask.run(FutureTask.java:264)
  java.base/java.util.concurrent.ThreadPoolExecutor.runWorker(ThreadPoolExecutor.java:1167)
  java.base/java.util.concurrent.ThreadPoolExecutor$Worker.run(ThreadPoolExecutor.java:641)
  java.base/java.lang.Thread.run(Thread.java:844)
]]>
      </failure>

          </testcase>
            <testcase name="feeTest3" time="0.080" classname="com.edu.test.TransFeeTest">
                <failure type="java.lang.AssertionError"
                  message="expected [请求失败] but found [success]"
              >
<![CDATA[java.lang.AssertionError: expected [请求失败] but found [success]
  org.testng.Assert.fail(Assert.java:96)
  org.testng.Assert.failNotEquals(Assert.java:776)
  org.testng.Assert.assertEqualsImpl(Assert.java:137)
  org.testng.Assert.assertEquals(Assert.java:118)
  org.testng.Assert.assertEquals(Assert.java:453)
  org.testng.Assert.assertEquals(Assert.java:463)
  com.edu.test.TransFeeTest.feeTest3(TransFeeTest.java:50)
  java.base/jdk.internal.reflect.NativeMethodAccessorImpl.invoke0(Native Method)
  java.base/jdk.internal.reflect.NativeMethodAccessorImpl.invoke(NativeMethodAccessorImpl.java:62)
  java.base/jdk.internal.reflect.DelegatingMethodAccessorImpl.invoke(DelegatingMethodAccessorImpl.java:43)
  java.base/java.lang.reflect.Method.invoke(Method.java:564)
  org.testng.internal.MethodInvocationHelper.invokeMethod(MethodInvocationHelper.java:124)
  org.testng.internal.Invoker.invokeMethod(Invoker.java:580)
  org.testng.internal.Invoker.invokeTestMethod(Invoker.java:716)
  org.testng.internal.Invoker.invokeTestMethods(Invoker.java:988)
  org.testng.internal.TestMethodWorker.invokeTestMethods(TestMethodWorker.java:125)
  org.testng.internal.TestMethodWorker.run(TestMethodWorker.java:109)
  org.testng.TestRunner.privateRun(TestRunner.java:648)
  org.testng.TestRunner.run(TestRunner.java:505)
  org.testng.SuiteRunner.runTest(SuiteRunner.java:455)
  org.testng.SuiteRunner.access$000(SuiteRunner.java:40)
  org.testng.SuiteRunner$SuiteWorker.run(SuiteRunner.java:489)
  org.testng.internal.thread.ThreadUtil$1.call(ThreadUtil.java:52)
  java.base/java.util.concurrent.FutureTask.run(FutureTask.java:264)
  java.base/java.util.concurrent.ThreadPoolExecutor.runWorker(ThreadPoolExecutor.java:1167)
  java.base/java.util.concurrent.ThreadPoolExecutor$Worker.run(ThreadPoolExecutor.java:641)
  java.base/java.lang.Thread.run(Thread.java:844)
]]>
      </failure>

          </testcase>
            <testcase name="feeTest8" time="0.083" classname="com.edu.test.TransFeeTest">
                <failure type="java.lang.AssertionError"
                  message="expected [请求失败] but found [success]"
              >
<![CDATA[java.lang.AssertionError: expected [请求失败] but found [success]
  org.testng.Assert.fail(Assert.java:96)
  org.testng.Assert.failNotEquals(Assert.java:776)
  org.testng.Assert.assertEqualsImpl(Assert.java:137)
  org.testng.Assert.assertEquals(Assert.java:118)
  org.testng.Assert.assertEquals(Assert.java:453)
  org.testng.Assert.assertEquals(Assert.java:463)
  com.edu.test.TransFeeTest.feeTest8(TransFeeTest.java:89)
  java.base/jdk.internal.reflect.NativeMethodAccessorImpl.invoke0(Native Method)
  java.base/jdk.internal.reflect.NativeMethodAccessorImpl.invoke(NativeMethodAccessorImpl.java:62)
  java.base/jdk.internal.reflect.DelegatingMethodAccessorImpl.invoke(DelegatingMethodAccessorImpl.java:43)
  java.base/java.lang.reflect.Method.invoke(Method.java:564)
  org.testng.internal.MethodInvocationHelper.invokeMethod(MethodInvocationHelper.java:124)
  org.testng.internal.Invoker.invokeMethod(Invoker.java:580)
  org.testng.internal.Invoker.invokeTestMethod(Invoker.java:716)
  org.testng.internal.Invoker.invokeTestMethods(Invoker.java:988)
  org.testng.internal.TestMethodWorker.invokeTestMethods(TestMethodWorker.java:125)
  org.testng.internal.TestMethodWorker.run(TestMethodWorker.java:109)
  org.testng.TestRunner.privateRun(TestRunner.java:648)
  org.testng.TestRunner.run(TestRunner.java:505)
  org.testng.SuiteRunner.runTest(SuiteRunner.java:455)
  org.testng.SuiteRunner.access$000(SuiteRunner.java:40)
  org.testng.SuiteRunner$SuiteWorker.run(SuiteRunner.java:489)
  org.testng.internal.thread.ThreadUtil$1.call(ThreadUtil.java:52)
  java.base/java.util.concurrent.FutureTask.run(FutureTask.java:264)
  java.base/java.util.concurrent.ThreadPoolExecutor.runWorker(ThreadPoolExecutor.java:1167)
  java.base/java.util.concurrent.ThreadPoolExecutor$Worker.run(ThreadPoolExecutor.java:641)
  java.base/java.lang.Thread.run(Thread.java:844)
]]>
      </failure>

          </testcase>
  
  
            <testcase name="feeTest" time="0.476" classname="com.edu.test.TransFeeTest" />
                <testcase name="feeTest4" time="0.094" classname="com.edu.test.TransFeeTest" />
                <testcase name="feeTest2" time="0.100" classname="com.edu.test.TransFeeTest" />
      
</testsuite>
